//Schematic to java Structure by jajo_11 | inspired by "MITHION'S .SCHEMATIC TO JAVA CONVERTINGTOOL"
package net.minecraft.theTitans.world;
import java.util.Random;
import net.minecraft.init.Blocks;
import net.minecraft.world.World;
import net.minecraft.world.gen.feature.WorldGenerator;
public class WorldGenSurvivalDome extends WorldGenerator
{
	public boolean generate(World world, Random rand, int x, int y, int z)
	{
		if (!world.getBlock(x, y - 1, z).isOpaqueCube())
		--y;
		else if (world.getBlock(x, y, z).isOpaqueCube())
		++y;
		else if (!world.isRemote && world.isAirBlock(x, y, z) && world.getBlock(x, y - 1, z).isOpaqueCube() && rand.nextInt(3) == 0)
		generate_r0(world, rand, x, y, z);
		return false;
	}

	public boolean generate_r0(World world, Random rand, int x, int y, int z)
	{
		x -= 5;
		x -= 2;
		z -= 7;
		world.setBlock(x + 3, y + 0, z + 1, Blocks.planks, 2, 3);
		world.setBlock(x + 4, y + 0, z + 1, Blocks.planks, 2, 3);
		world.setBlock(x + 5, y + 0, z + 1, Blocks.planks, 2, 3);
		world.setBlock(x + 6, y + 0, z + 1, Blocks.planks, 2, 3);
		world.setBlock(x + 2, y + 0, z + 2, Blocks.planks, 2, 3);
		world.setBlock(x + 3, y + 0, z + 2, Blocks.planks, 2, 3);
		world.setBlock(x + 4, y + 0, z + 2, Blocks.planks, 2, 3);
		world.setBlock(x + 5, y + 0, z + 2, Blocks.planks, 2, 3);
		world.setBlock(x + 6, y + 0, z + 2, Blocks.planks, 2, 3);
		world.setBlock(x + 7, y + 0, z + 2, Blocks.planks, 2, 3);
		world.setBlock(x + 1, y + 0, z + 3, Blocks.planks, 2, 3);
		world.setBlock(x + 2, y + 0, z + 3, Blocks.planks, 2, 3);
		world.setBlock(x + 3, y + 0, z + 3, Blocks.planks, 2, 3);
		world.setBlock(x + 4, y + 0, z + 3, Blocks.planks, 2, 3);
		world.setBlock(x + 5, y + 0, z + 3, Blocks.planks, 2, 3);
		world.setBlock(x + 6, y + 0, z + 3, Blocks.planks, 2, 3);
		world.setBlock(x + 7, y + 0, z + 3, Blocks.planks, 2, 3);
		world.setBlock(x + 8, y + 0, z + 3, Blocks.planks, 2, 3);
		world.setBlock(x + 1, y + 0, z + 4, Blocks.planks, 2, 3);
		world.setBlock(x + 2, y + 0, z + 4, Blocks.planks, 2, 3);
		world.setBlock(x + 3, y + 0, z + 4, Blocks.planks, 2, 3);
		world.setBlock(x + 4, y + 0, z + 4, Blocks.planks, 2, 3);
		world.setBlock(x + 5, y + 0, z + 4, Blocks.planks, 2, 3);
		world.setBlock(x + 6, y + 0, z + 4, Blocks.planks, 2, 3);
		world.setBlock(x + 7, y + 0, z + 4, Blocks.planks, 2, 3);
		world.setBlock(x + 8, y + 0, z + 4, Blocks.planks, 2, 3);
		world.setBlock(x + 1, y + 0, z + 5, Blocks.planks, 2, 3);
		world.setBlock(x + 2, y + 0, z + 5, Blocks.planks, 2, 3);
		world.setBlock(x + 3, y + 0, z + 5, Blocks.planks, 2, 3);
		world.setBlock(x + 4, y + 0, z + 5, Blocks.planks, 2, 3);
		world.setBlock(x + 5, y + 0, z + 5, Blocks.planks, 2, 3);
		world.setBlock(x + 6, y + 0, z + 5, Blocks.planks, 2, 3);
		world.setBlock(x + 7, y + 0, z + 5, Blocks.planks, 2, 3);
		world.setBlock(x + 8, y + 0, z + 5, Blocks.planks, 2, 3);
		world.setBlock(x + 0, y + 0, z + 6, Blocks.planks, 2, 3);
		world.setBlock(x + 1, y + 0, z + 6, Blocks.planks, 2, 3);
		world.setBlock(x + 2, y + 0, z + 6, Blocks.planks, 2, 3);
		world.setBlock(x + 3, y + 0, z + 6, Blocks.planks, 2, 3);
		world.setBlock(x + 4, y + 0, z + 6, Blocks.planks, 2, 3);
		world.setBlock(x + 5, y + 0, z + 6, Blocks.planks, 2, 3);
		world.setBlock(x + 6, y + 0, z + 6, Blocks.planks, 2, 3);
		world.setBlock(x + 7, y + 0, z + 6, Blocks.planks, 2, 3);
		world.setBlock(x + 8, y + 0, z + 6, Blocks.planks, 2, 3);
		world.setBlock(x + 0, y + 0, z + 7, Blocks.planks, 2, 3);
		world.setBlock(x + 1, y + 0, z + 7, Blocks.planks, 2, 3);
		world.setBlock(x + 2, y + 0, z + 7, Blocks.planks, 2, 3);
		world.setBlock(x + 3, y + 0, z + 7, Blocks.planks, 2, 3);
		world.setBlock(x + 4, y + 0, z + 7, Blocks.planks, 2, 3);
		world.setBlock(x + 5, y + 0, z + 7, Blocks.planks, 2, 3);
		world.setBlock(x + 6, y + 0, z + 7, Blocks.planks, 2, 3);
		world.setBlock(x + 7, y + 0, z + 7, Blocks.planks, 2, 3);
		world.setBlock(x + 8, y + 0, z + 7, Blocks.planks, 2, 3);
		world.setBlock(x + 1, y + 0, z + 8, Blocks.planks, 2, 3);
		world.setBlock(x + 2, y + 0, z + 8, Blocks.planks, 2, 3);
		world.setBlock(x + 3, y + 0, z + 8, Blocks.planks, 2, 3);
		world.setBlock(x + 4, y + 0, z + 8, Blocks.planks, 2, 3);
		world.setBlock(x + 5, y + 0, z + 8, Blocks.planks, 2, 3);
		world.setBlock(x + 6, y + 0, z + 8, Blocks.planks, 2, 3);
		world.setBlock(x + 7, y + 0, z + 8, Blocks.planks, 2, 3);
		world.setBlock(x + 8, y + 0, z + 8, Blocks.planks, 2, 3);
		world.setBlock(x + 1, y + 0, z + 9, Blocks.planks, 2, 3);
		world.setBlock(x + 2, y + 0, z + 9, Blocks.planks, 2, 3);
		world.setBlock(x + 3, y + 0, z + 9, Blocks.planks, 2, 3);
		world.setBlock(x + 4, y + 0, z + 9, Blocks.planks, 2, 3);
		world.setBlock(x + 5, y + 0, z + 9, Blocks.planks, 2, 3);
		world.setBlock(x + 6, y + 0, z + 9, Blocks.planks, 2, 3);
		world.setBlock(x + 7, y + 0, z + 9, Blocks.planks, 2, 3);
		world.setBlock(x + 8, y + 0, z + 9, Blocks.planks, 2, 3);
		world.setBlock(x + 1, y + 0, z + 10, Blocks.planks, 2, 3);
		world.setBlock(x + 2, y + 0, z + 10, Blocks.planks, 2, 3);
		world.setBlock(x + 3, y + 0, z + 10, Blocks.planks, 2, 3);
		world.setBlock(x + 4, y + 0, z + 10, Blocks.planks, 2, 3);
		world.setBlock(x + 5, y + 0, z + 10, Blocks.planks, 2, 3);
		world.setBlock(x + 6, y + 0, z + 10, Blocks.planks, 2, 3);
		world.setBlock(x + 7, y + 0, z + 10, Blocks.planks, 2, 3);
		world.setBlock(x + 8, y + 0, z + 10, Blocks.planks, 2, 3);
		world.setBlock(x + 2, y + 0, z + 11, Blocks.planks, 2, 3);
		world.setBlock(x + 3, y + 0, z + 11, Blocks.planks, 2, 3);
		world.setBlock(x + 4, y + 0, z + 11, Blocks.planks, 2, 3);
		world.setBlock(x + 5, y + 0, z + 11, Blocks.planks, 2, 3);
		world.setBlock(x + 6, y + 0, z + 11, Blocks.planks, 2, 3);
		world.setBlock(x + 7, y + 0, z + 11, Blocks.planks, 2, 3);
		world.setBlock(x + 3, y + 0, z + 12, Blocks.planks, 2, 3);
		world.setBlock(x + 4, y + 0, z + 12, Blocks.planks, 2, 3);
		world.setBlock(x + 5, y + 0, z + 12, Blocks.planks, 2, 3);
		world.setBlock(x + 6, y + 0, z + 12, Blocks.planks, 2, 3);
		world.setBlock(x + 3, y + 1, z + 0, Blocks.planks, 1, 3);
		world.setBlock(x + 4, y + 1, z + 0, Blocks.planks, 1, 3);
		world.setBlock(x + 5, y + 1, z + 0, Blocks.planks, 1, 3);
		world.setBlock(x + 6, y + 1, z + 0, Blocks.planks, 1, 3);
		world.setBlock(x + 2, y + 1, z + 1, Blocks.planks, 1, 3);
		world.setBlock(x + 3, y + 1, z + 1, Blocks.chest, 3, 3);
		world.setBlock(x + 4, y + 1, z + 1, Blocks.crafting_table, 0, 3);
		world.setBlock(x + 5, y + 1, z + 1, Blocks.crafting_table, 0, 3);
		world.setBlock(x + 6, y + 1, z + 1, Blocks.chest, 3, 3);
		world.setBlock(x + 7, y + 1, z + 1, Blocks.planks, 1, 3);
		world.setBlock(x + 1, y + 1, z + 2, Blocks.planks, 1, 3);
		world.setBlock(x + 2, y + 1, z + 2, Blocks.bed, 10, 3);
		world.setBlock(x + 3, y + 1, z + 2, Blocks.air, 0, 3);
		world.setBlock(x + 4, y + 1, z + 2, Blocks.air, 0, 3);
		world.setBlock(x + 5, y + 1, z + 2, Blocks.air, 0, 3);
		world.setBlock(x + 6, y + 1, z + 2, Blocks.air, 0, 3);
		world.setBlock(x + 7, y + 1, z + 2, Blocks.bed, 10, 3);
		world.setBlock(x + 8, y + 1, z + 2, Blocks.planks, 1, 3);
		world.setBlock(x + 0, y + 1, z + 3, Blocks.planks, 1, 3);
		world.setBlock(x + 1, y + 1, z + 3, Blocks.air, 0, 3);
		world.setBlock(x + 2, y + 1, z + 3, Blocks.bed, 2, 3);
		world.setBlock(x + 3, y + 1, z + 3, Blocks.air, 0, 3);
		world.setBlock(x + 4, y + 1, z + 3, Blocks.air, 0, 3);
		world.setBlock(x + 5, y + 1, z + 3, Blocks.air, 0, 3);
		world.setBlock(x + 6, y + 1, z + 3, Blocks.air, 0, 3);
		world.setBlock(x + 7, y + 1, z + 3, Blocks.bed, 2, 3);
		world.setBlock(x + 8, y + 1, z + 3, Blocks.air, 0, 3);
		world.setBlock(x + 9, y + 1, z + 3, Blocks.planks, 1, 3);
		world.setBlock(x + 0, y + 1, z + 4, Blocks.planks, 1, 3);
		world.setBlock(x + 1, y + 1, z + 4, Blocks.air, 0, 3);
		world.setBlock(x + 2, y + 1, z + 4, Blocks.air, 0, 3);
		world.setBlock(x + 3, y + 1, z + 4, Blocks.air, 0, 3);
		world.setBlock(x + 4, y + 1, z + 4, Blocks.air, 0, 3);
		world.setBlock(x + 5, y + 1, z + 4, Blocks.air, 0, 3);
		world.setBlock(x + 6, y + 1, z + 4, Blocks.air, 0, 3);
		world.setBlock(x + 7, y + 1, z + 4, Blocks.air, 0, 3);
		world.setBlock(x + 8, y + 1, z + 4, Blocks.air, 0, 3);
		world.setBlock(x + 9, y + 1, z + 4, Blocks.planks, 1, 3);
		world.setBlock(x + 0, y + 1, z + 5, Blocks.planks, 1, 3);
		world.setBlock(x + 1, y + 1, z + 5, Blocks.air, 0, 3);
		world.setBlock(x + 2, y + 1, z + 5, Blocks.air, 0, 3);
		world.setBlock(x + 3, y + 1, z + 5, Blocks.air, 0, 3);
		world.setBlock(x + 4, y + 1, z + 5, Blocks.air, 0, 3);
		world.setBlock(x + 5, y + 1, z + 5, Blocks.air, 0, 3);
		world.setBlock(x + 6, y + 1, z + 5, Blocks.air, 0, 3);
		world.setBlock(x + 7, y + 1, z + 5, Blocks.air, 0, 3);
		world.setBlock(x + 8, y + 1, z + 5, Blocks.air, 0, 3);
		world.setBlock(x + 9, y + 1, z + 5, Blocks.planks, 1, 3);
		world.setBlock(x + 0, y + 1, z + 6, Blocks.wooden_door, 0, 3);
		world.setBlock(x + 1, y + 1, z + 6, Blocks.air, 0, 3);
		world.setBlock(x + 2, y + 1, z + 6, Blocks.air, 0, 3);
		world.setBlock(x + 3, y + 1, z + 6, Blocks.air, 0, 3);
		world.setBlock(x + 4, y + 1, z + 6, Blocks.air, 0, 3);
		world.setBlock(x + 5, y + 1, z + 6, Blocks.air, 0, 3);
		world.setBlock(x + 6, y + 1, z + 6, Blocks.air, 0, 3);
		world.setBlock(x + 7, y + 1, z + 6, Blocks.air, 0, 3);
		world.setBlock(x + 8, y + 1, z + 6, Blocks.air, 0, 3);
		world.setBlock(x + 9, y + 1, z + 6, Blocks.planks, 1, 3);
		world.setBlock(x + 0, y + 1, z + 7, Blocks.wooden_door, 0, 3);
		world.setBlock(x + 1, y + 1, z + 7, Blocks.air, 0, 3);
		world.setBlock(x + 2, y + 1, z + 7, Blocks.air, 0, 3);
		world.setBlock(x + 3, y + 1, z + 7, Blocks.air, 0, 3);
		world.setBlock(x + 4, y + 1, z + 7, Blocks.air, 0, 3);
		world.setBlock(x + 5, y + 1, z + 7, Blocks.air, 0, 3);
		world.setBlock(x + 6, y + 1, z + 7, Blocks.air, 0, 3);
		world.setBlock(x + 7, y + 1, z + 7, Blocks.air, 0, 3);
		world.setBlock(x + 8, y + 1, z + 7, Blocks.air, 0, 3);
		world.setBlock(x + 9, y + 1, z + 7, Blocks.planks, 1, 3);
		world.setBlock(x + 0, y + 1, z + 8, Blocks.planks, 1, 3);
		world.setBlock(x + 1, y + 1, z + 8, Blocks.air, 0, 3);
		world.setBlock(x + 2, y + 1, z + 8, Blocks.air, 0, 3);
		world.setBlock(x + 3, y + 1, z + 8, Blocks.air, 0, 3);
		world.setBlock(x + 4, y + 1, z + 8, Blocks.air, 0, 3);
		world.setBlock(x + 5, y + 1, z + 8, Blocks.air, 0, 3);
		world.setBlock(x + 6, y + 1, z + 8, Blocks.air, 0, 3);
		world.setBlock(x + 7, y + 1, z + 8, Blocks.air, 0, 3);
		world.setBlock(x + 8, y + 1, z + 8, Blocks.air, 0, 3);
		world.setBlock(x + 9, y + 1, z + 8, Blocks.planks, 1, 3);
		world.setBlock(x + 0, y + 1, z + 9, Blocks.planks, 1, 3);
		world.setBlock(x + 1, y + 1, z + 9, Blocks.air, 0, 3);
		world.setBlock(x + 2, y + 1, z + 9, Blocks.air, 0, 3);
		world.setBlock(x + 3, y + 1, z + 9, Blocks.air, 0, 3);
		world.setBlock(x + 4, y + 1, z + 9, Blocks.air, 0, 3);
		world.setBlock(x + 5, y + 1, z + 9, Blocks.air, 0, 3);
		world.setBlock(x + 6, y + 1, z + 9, Blocks.air, 0, 3);
		world.setBlock(x + 7, y + 1, z + 9, Blocks.air, 0, 3);
		world.setBlock(x + 8, y + 1, z + 9, Blocks.air, 0, 3);
		world.setBlock(x + 9, y + 1, z + 9, Blocks.planks, 1, 3);
		world.setBlock(x + 0, y + 1, z + 10, Blocks.planks, 1, 3);
		world.setBlock(x + 1, y + 1, z + 10, Blocks.air, 0, 3);
		world.setBlock(x + 2, y + 1, z + 10, Blocks.bed, 0, 3);
		world.setBlock(x + 3, y + 1, z + 10, Blocks.air, 0, 3);
		world.setBlock(x + 4, y + 1, z + 10, Blocks.air, 0, 3);
		world.setBlock(x + 5, y + 1, z + 10, Blocks.air, 0, 3);
		world.setBlock(x + 6, y + 1, z + 10, Blocks.air, 0, 3);
		world.setBlock(x + 7, y + 1, z + 10, Blocks.bed, 0, 3);
		world.setBlock(x + 8, y + 1, z + 10, Blocks.air, 0, 3);
		world.setBlock(x + 9, y + 1, z + 10, Blocks.planks, 1, 3);
		world.setBlock(x + 1, y + 1, z + 11, Blocks.planks, 1, 3);
		world.setBlock(x + 2, y + 1, z + 11, Blocks.bed, 8, 3);
		world.setBlock(x + 3, y + 1, z + 11, Blocks.air, 0, 3);
		world.setBlock(x + 4, y + 1, z + 11, Blocks.air, 0, 3);
		world.setBlock(x + 5, y + 1, z + 11, Blocks.air, 0, 3);
		world.setBlock(x + 6, y + 1, z + 11, Blocks.air, 0, 3);
		world.setBlock(x + 7, y + 1, z + 11, Blocks.bed, 8, 3);
		world.setBlock(x + 8, y + 1, z + 11, Blocks.planks, 1, 3);
		world.setBlock(x + 2, y + 1, z + 12, Blocks.planks, 1, 3);
		world.setBlock(x + 3, y + 1, z + 12, Blocks.chest, 2, 3);
		world.setBlock(x + 4, y + 1, z + 12, Blocks.crafting_table, 0, 3);
		world.setBlock(x + 5, y + 1, z + 12, Blocks.crafting_table, 0, 3);
		world.setBlock(x + 6, y + 1, z + 12, Blocks.chest, 2, 3);
		world.setBlock(x + 7, y + 1, z + 12, Blocks.planks, 1, 3);
		world.setBlock(x + 3, y + 1, z + 13, Blocks.planks, 1, 3);
		world.setBlock(x + 4, y + 1, z + 13, Blocks.planks, 1, 3);
		world.setBlock(x + 5, y + 1, z + 13, Blocks.planks, 1, 3);
		world.setBlock(x + 6, y + 1, z + 13, Blocks.planks, 1, 3);
		world.setBlock(x + 3, y + 2, z + 0, Blocks.glass, 0, 3);
		world.setBlock(x + 4, y + 2, z + 0, Blocks.glass, 0, 3);
		world.setBlock(x + 5, y + 2, z + 0, Blocks.glass, 0, 3);
		world.setBlock(x + 6, y + 2, z + 0, Blocks.glass, 0, 3);
		world.setBlock(x + 2, y + 2, z + 1, Blocks.glass, 0, 3);
		world.setBlock(x + 3, y + 2, z + 1, Blocks.air, 0, 3);
		world.setBlock(x + 4, y + 2, z + 1, Blocks.air, 0, 3);
		world.setBlock(x + 5, y + 2, z + 1, Blocks.air, 0, 3);
		world.setBlock(x + 6, y + 2, z + 1, Blocks.air, 0, 3);
		world.setBlock(x + 7, y + 2, z + 1, Blocks.glass, 0, 3);
		world.setBlock(x + 1, y + 2, z + 2, Blocks.glass, 0, 3);
		world.setBlock(x + 2, y + 2, z + 2, Blocks.air, 0, 3);
		world.setBlock(x + 3, y + 2, z + 2, Blocks.air, 0, 3);
		world.setBlock(x + 4, y + 2, z + 2, Blocks.air, 0, 3);
		world.setBlock(x + 5, y + 2, z + 2, Blocks.air, 0, 3);
		world.setBlock(x + 6, y + 2, z + 2, Blocks.air, 0, 3);
		world.setBlock(x + 7, y + 2, z + 2, Blocks.air, 0, 3);
		world.setBlock(x + 8, y + 2, z + 2, Blocks.glass, 0, 3);
		world.setBlock(x + 0, y + 2, z + 3, Blocks.glass, 0, 3);
		world.setBlock(x + 1, y + 2, z + 3, Blocks.air, 0, 3);
		world.setBlock(x + 2, y + 2, z + 3, Blocks.air, 0, 3);
		world.setBlock(x + 3, y + 2, z + 3, Blocks.air, 0, 3);
		world.setBlock(x + 4, y + 2, z + 3, Blocks.air, 0, 3);
		world.setBlock(x + 5, y + 2, z + 3, Blocks.air, 0, 3);
		world.setBlock(x + 6, y + 2, z + 3, Blocks.air, 0, 3);
		world.setBlock(x + 7, y + 2, z + 3, Blocks.air, 0, 3);
		world.setBlock(x + 8, y + 2, z + 3, Blocks.air, 0, 3);
		world.setBlock(x + 9, y + 2, z + 3, Blocks.glass, 0, 3);
		world.setBlock(x + 0, y + 2, z + 4, Blocks.glass, 0, 3);
		world.setBlock(x + 1, y + 2, z + 4, Blocks.air, 0, 3);
		world.setBlock(x + 2, y + 2, z + 4, Blocks.air, 0, 3);
		world.setBlock(x + 3, y + 2, z + 4, Blocks.air, 0, 3);
		world.setBlock(x + 4, y + 2, z + 4, Blocks.air, 0, 3);
		world.setBlock(x + 5, y + 2, z + 4, Blocks.air, 0, 3);
		world.setBlock(x + 6, y + 2, z + 4, Blocks.air, 0, 3);
		world.setBlock(x + 7, y + 2, z + 4, Blocks.air, 0, 3);
		world.setBlock(x + 8, y + 2, z + 4, Blocks.air, 0, 3);
		world.setBlock(x + 9, y + 2, z + 4, Blocks.glass, 0, 3);
		world.setBlock(x + 0, y + 2, z + 5, Blocks.glass, 0, 3);
		world.setBlock(x + 1, y + 2, z + 5, Blocks.air, 0, 3);
		world.setBlock(x + 2, y + 2, z + 5, Blocks.air, 0, 3);
		world.setBlock(x + 3, y + 2, z + 5, Blocks.air, 0, 3);
		world.setBlock(x + 4, y + 2, z + 5, Blocks.air, 0, 3);
		world.setBlock(x + 5, y + 2, z + 5, Blocks.air, 0, 3);
		world.setBlock(x + 6, y + 2, z + 5, Blocks.air, 0, 3);
		world.setBlock(x + 7, y + 2, z + 5, Blocks.air, 0, 3);
		world.setBlock(x + 8, y + 2, z + 5, Blocks.air, 0, 3);
		world.setBlock(x + 9, y + 2, z + 5, Blocks.glass, 0, 3);
		world.setBlock(x + 0, y + 2, z + 6, Blocks.wooden_door, 8, 3);
		world.setBlock(x + 1, y + 2, z + 6, Blocks.air, 0, 3);
		world.setBlock(x + 2, y + 2, z + 6, Blocks.air, 0, 3);
		world.setBlock(x + 3, y + 2, z + 6, Blocks.air, 0, 3);
		world.setBlock(x + 4, y + 2, z + 6, Blocks.air, 0, 3);
		world.setBlock(x + 5, y + 2, z + 6, Blocks.air, 0, 3);
		world.setBlock(x + 6, y + 2, z + 6, Blocks.air, 0, 3);
		world.setBlock(x + 7, y + 2, z + 6, Blocks.air, 0, 3);
		world.setBlock(x + 8, y + 2, z + 6, Blocks.air, 0, 3);
		world.setBlock(x + 9, y + 2, z + 6, Blocks.glass, 0, 3);
		world.setBlock(x + 0, y + 2, z + 7, Blocks.wooden_door, 9, 3);
		world.setBlock(x + 1, y + 2, z + 7, Blocks.air, 0, 3);
		world.setBlock(x + 2, y + 2, z + 7, Blocks.air, 0, 3);
		world.setBlock(x + 3, y + 2, z + 7, Blocks.air, 0, 3);
		world.setBlock(x + 4, y + 2, z + 7, Blocks.air, 0, 3);
		world.setBlock(x + 5, y + 2, z + 7, Blocks.air, 0, 3);
		world.setBlock(x + 6, y + 2, z + 7, Blocks.air, 0, 3);
		world.setBlock(x + 7, y + 2, z + 7, Blocks.air, 0, 3);
		world.setBlock(x + 8, y + 2, z + 7, Blocks.air, 0, 3);
		world.setBlock(x + 9, y + 2, z + 7, Blocks.glass, 0, 3);
		world.setBlock(x + 0, y + 2, z + 8, Blocks.glass, 0, 3);
		world.setBlock(x + 1, y + 2, z + 8, Blocks.air, 0, 3);
		world.setBlock(x + 2, y + 2, z + 8, Blocks.air, 0, 3);
		world.setBlock(x + 3, y + 2, z + 8, Blocks.air, 0, 3);
		world.setBlock(x + 4, y + 2, z + 8, Blocks.air, 0, 3);
		world.setBlock(x + 5, y + 2, z + 8, Blocks.air, 0, 3);
		world.setBlock(x + 6, y + 2, z + 8, Blocks.air, 0, 3);
		world.setBlock(x + 7, y + 2, z + 8, Blocks.air, 0, 3);
		world.setBlock(x + 8, y + 2, z + 8, Blocks.air, 0, 3);
		world.setBlock(x + 9, y + 2, z + 8, Blocks.glass, 0, 3);
		world.setBlock(x + 0, y + 2, z + 9, Blocks.glass, 0, 3);
		world.setBlock(x + 1, y + 2, z + 9, Blocks.air, 0, 3);
		world.setBlock(x + 2, y + 2, z + 9, Blocks.air, 0, 3);
		world.setBlock(x + 3, y + 2, z + 9, Blocks.air, 0, 3);
		world.setBlock(x + 4, y + 2, z + 9, Blocks.air, 0, 3);
		world.setBlock(x + 5, y + 2, z + 9, Blocks.air, 0, 3);
		world.setBlock(x + 6, y + 2, z + 9, Blocks.air, 0, 3);
		world.setBlock(x + 7, y + 2, z + 9, Blocks.air, 0, 3);
		world.setBlock(x + 8, y + 2, z + 9, Blocks.air, 0, 3);
		world.setBlock(x + 9, y + 2, z + 9, Blocks.glass, 0, 3);
		world.setBlock(x + 0, y + 2, z + 10, Blocks.glass, 0, 3);
		world.setBlock(x + 1, y + 2, z + 10, Blocks.air, 0, 3);
		world.setBlock(x + 2, y + 2, z + 10, Blocks.air, 0, 3);
		world.setBlock(x + 3, y + 2, z + 10, Blocks.air, 0, 3);
		world.setBlock(x + 4, y + 2, z + 10, Blocks.air, 0, 3);
		world.setBlock(x + 5, y + 2, z + 10, Blocks.air, 0, 3);
		world.setBlock(x + 6, y + 2, z + 10, Blocks.air, 0, 3);
		world.setBlock(x + 7, y + 2, z + 10, Blocks.air, 0, 3);
		world.setBlock(x + 8, y + 2, z + 10, Blocks.air, 0, 3);
		world.setBlock(x + 9, y + 2, z + 10, Blocks.glass, 0, 3);
		world.setBlock(x + 1, y + 2, z + 11, Blocks.glass, 0, 3);
		world.setBlock(x + 2, y + 2, z + 11, Blocks.air, 0, 3);
		world.setBlock(x + 3, y + 2, z + 11, Blocks.air, 0, 3);
		world.setBlock(x + 4, y + 2, z + 11, Blocks.air, 0, 3);
		world.setBlock(x + 5, y + 2, z + 11, Blocks.air, 0, 3);
		world.setBlock(x + 6, y + 2, z + 11, Blocks.air, 0, 3);
		world.setBlock(x + 7, y + 2, z + 11, Blocks.air, 0, 3);
		world.setBlock(x + 8, y + 2, z + 11, Blocks.glass, 0, 3);
		world.setBlock(x + 2, y + 2, z + 12, Blocks.glass, 0, 3);
		world.setBlock(x + 3, y + 2, z + 12, Blocks.air, 0, 3);
		world.setBlock(x + 4, y + 2, z + 12, Blocks.air, 0, 3);
		world.setBlock(x + 5, y + 2, z + 12, Blocks.air, 0, 3);
		world.setBlock(x + 6, y + 2, z + 12, Blocks.air, 0, 3);
		world.setBlock(x + 7, y + 2, z + 12, Blocks.glass, 0, 3);
		world.setBlock(x + 3, y + 2, z + 13, Blocks.glass, 0, 3);
		world.setBlock(x + 4, y + 2, z + 13, Blocks.glass, 0, 3);
		world.setBlock(x + 5, y + 2, z + 13, Blocks.glass, 0, 3);
		world.setBlock(x + 6, y + 2, z + 13, Blocks.glass, 0, 3);
		world.setBlock(x + 3, y + 3, z + 1, Blocks.glass, 0, 3);
		world.setBlock(x + 4, y + 3, z + 1, Blocks.glass, 0, 3);
		world.setBlock(x + 5, y + 3, z + 1, Blocks.glass, 0, 3);
		world.setBlock(x + 6, y + 3, z + 1, Blocks.glass, 0, 3);
		world.setBlock(x + 2, y + 3, z + 2, Blocks.glass, 0, 3);
		world.setBlock(x + 3, y + 3, z + 2, Blocks.glass, 0, 3);
		world.setBlock(x + 4, y + 3, z + 2, Blocks.air, 0, 3);
		world.setBlock(x + 5, y + 3, z + 2, Blocks.air, 0, 3);
		world.setBlock(x + 6, y + 3, z + 2, Blocks.glass, 0, 3);
		world.setBlock(x + 7, y + 3, z + 2, Blocks.glass, 0, 3);
		world.setBlock(x + 1, y + 3, z + 3, Blocks.glass, 0, 3);
		world.setBlock(x + 2, y + 3, z + 3, Blocks.glass, 0, 3);
		world.setBlock(x + 3, y + 3, z + 3, Blocks.air, 0, 3);
		world.setBlock(x + 4, y + 3, z + 3, Blocks.air, 0, 3);
		world.setBlock(x + 5, y + 3, z + 3, Blocks.air, 0, 3);
		world.setBlock(x + 6, y + 3, z + 3, Blocks.air, 0, 3);
		world.setBlock(x + 7, y + 3, z + 3, Blocks.glass, 0, 3);
		world.setBlock(x + 8, y + 3, z + 3, Blocks.glass, 0, 3);
		world.setBlock(x + 1, y + 3, z + 4, Blocks.glass, 0, 3);
		world.setBlock(x + 2, y + 3, z + 4, Blocks.air, 0, 3);
		world.setBlock(x + 3, y + 3, z + 4, Blocks.air, 0, 3);
		world.setBlock(x + 4, y + 3, z + 4, Blocks.air, 0, 3);
		world.setBlock(x + 5, y + 3, z + 4, Blocks.air, 0, 3);
		world.setBlock(x + 6, y + 3, z + 4, Blocks.air, 0, 3);
		world.setBlock(x + 7, y + 3, z + 4, Blocks.air, 0, 3);
		world.setBlock(x + 8, y + 3, z + 4, Blocks.glass, 0, 3);
		world.setBlock(x + 0, y + 3, z + 5, Blocks.glass, 0, 3);
		world.setBlock(x + 1, y + 3, z + 5, Blocks.glass, 0, 3);
		world.setBlock(x + 2, y + 3, z + 5, Blocks.air, 0, 3);
		world.setBlock(x + 3, y + 3, z + 5, Blocks.air, 0, 3);
		world.setBlock(x + 4, y + 3, z + 5, Blocks.air, 0, 3);
		world.setBlock(x + 5, y + 3, z + 5, Blocks.air, 0, 3);
		world.setBlock(x + 6, y + 3, z + 5, Blocks.air, 0, 3);
		world.setBlock(x + 7, y + 3, z + 5, Blocks.air, 0, 3);
		world.setBlock(x + 8, y + 3, z + 5, Blocks.glass, 0, 3);
		world.setBlock(x + 0, y + 3, z + 6, Blocks.glass, 0, 3);
		world.setBlock(x + 1, y + 3, z + 6, Blocks.air, 0, 3);
		world.setBlock(x + 2, y + 3, z + 6, Blocks.air, 0, 3);
		world.setBlock(x + 3, y + 3, z + 6, Blocks.air, 0, 3);
		world.setBlock(x + 4, y + 3, z + 6, Blocks.air, 0, 3);
		world.setBlock(x + 5, y + 3, z + 6, Blocks.air, 0, 3);
		world.setBlock(x + 6, y + 3, z + 6, Blocks.air, 0, 3);
		world.setBlock(x + 7, y + 3, z + 6, Blocks.air, 0, 3);
		world.setBlock(x + 8, y + 3, z + 6, Blocks.glass, 0, 3);
		world.setBlock(x + 0, y + 3, z + 7, Blocks.glass, 0, 3);
		world.setBlock(x + 1, y + 3, z + 7, Blocks.air, 0, 3);
		world.setBlock(x + 2, y + 3, z + 7, Blocks.air, 0, 3);
		world.setBlock(x + 3, y + 3, z + 7, Blocks.air, 0, 3);
		world.setBlock(x + 4, y + 3, z + 7, Blocks.air, 0, 3);
		world.setBlock(x + 5, y + 3, z + 7, Blocks.air, 0, 3);
		world.setBlock(x + 6, y + 3, z + 7, Blocks.air, 0, 3);
		world.setBlock(x + 7, y + 3, z + 7, Blocks.air, 0, 3);
		world.setBlock(x + 8, y + 3, z + 7, Blocks.glass, 0, 3);
		world.setBlock(x + 0, y + 3, z + 8, Blocks.glass, 0, 3);
		world.setBlock(x + 1, y + 3, z + 8, Blocks.glass, 0, 3);
		world.setBlock(x + 2, y + 3, z + 8, Blocks.air, 0, 3);
		world.setBlock(x + 3, y + 3, z + 8, Blocks.air, 0, 3);
		world.setBlock(x + 4, y + 3, z + 8, Blocks.air, 0, 3);
		world.setBlock(x + 5, y + 3, z + 8, Blocks.air, 0, 3);
		world.setBlock(x + 6, y + 3, z + 8, Blocks.air, 0, 3);
		world.setBlock(x + 7, y + 3, z + 8, Blocks.air, 0, 3);
		world.setBlock(x + 8, y + 3, z + 8, Blocks.glass, 0, 3);
		world.setBlock(x + 1, y + 3, z + 9, Blocks.glass, 0, 3);
		world.setBlock(x + 2, y + 3, z + 9, Blocks.air, 0, 3);
		world.setBlock(x + 3, y + 3, z + 9, Blocks.air, 0, 3);
		world.setBlock(x + 4, y + 3, z + 9, Blocks.air, 0, 3);
		world.setBlock(x + 5, y + 3, z + 9, Blocks.air, 0, 3);
		world.setBlock(x + 6, y + 3, z + 9, Blocks.air, 0, 3);
		world.setBlock(x + 7, y + 3, z + 9, Blocks.air, 0, 3);
		world.setBlock(x + 8, y + 3, z + 9, Blocks.glass, 0, 3);
		world.setBlock(x + 1, y + 3, z + 10, Blocks.glass, 0, 3);
		world.setBlock(x + 2, y + 3, z + 10, Blocks.glass, 0, 3);
		world.setBlock(x + 3, y + 3, z + 10, Blocks.air, 0, 3);
		world.setBlock(x + 4, y + 3, z + 10, Blocks.air, 0, 3);
		world.setBlock(x + 5, y + 3, z + 10, Blocks.air, 0, 3);
		world.setBlock(x + 6, y + 3, z + 10, Blocks.air, 0, 3);
		world.setBlock(x + 7, y + 3, z + 10, Blocks.glass, 0, 3);
		world.setBlock(x + 8, y + 3, z + 10, Blocks.glass, 0, 3);
		world.setBlock(x + 2, y + 3, z + 11, Blocks.glass, 0, 3);
		world.setBlock(x + 3, y + 3, z + 11, Blocks.glass, 0, 3);
		world.setBlock(x + 4, y + 3, z + 11, Blocks.air, 0, 3);
		world.setBlock(x + 5, y + 3, z + 11, Blocks.air, 0, 3);
		world.setBlock(x + 6, y + 3, z + 11, Blocks.glass, 0, 3);
		world.setBlock(x + 7, y + 3, z + 11, Blocks.glass, 0, 3);
		world.setBlock(x + 3, y + 3, z + 12, Blocks.glass, 0, 3);
		world.setBlock(x + 4, y + 3, z + 12, Blocks.glass, 0, 3);
		world.setBlock(x + 5, y + 3, z + 12, Blocks.glass, 0, 3);
		world.setBlock(x + 6, y + 3, z + 12, Blocks.glass, 0, 3);
		world.setBlock(x + 4, y + 4, z + 2, Blocks.glass, 0, 3);
		world.setBlock(x + 5, y + 4, z + 2, Blocks.glass, 0, 3);
		world.setBlock(x + 3, y + 4, z + 3, Blocks.glass, 0, 3);
		world.setBlock(x + 4, y + 4, z + 3, Blocks.glass, 0, 3);
		world.setBlock(x + 5, y + 4, z + 3, Blocks.glass, 0, 3);
		world.setBlock(x + 6, y + 4, z + 3, Blocks.glass, 0, 3);
		world.setBlock(x + 2, y + 4, z + 4, Blocks.glass, 0, 3);
		world.setBlock(x + 3, y + 4, z + 4, Blocks.glass, 0, 3);
		world.setBlock(x + 4, y + 4, z + 4, Blocks.glass, 0, 3);
		world.setBlock(x + 5, y + 4, z + 4, Blocks.glass, 0, 3);
		world.setBlock(x + 6, y + 4, z + 4, Blocks.glass, 0, 3);
		world.setBlock(x + 7, y + 4, z + 4, Blocks.glass, 0, 3);
		world.setBlock(x + 1, y + 4, z + 5, Blocks.glass, 0, 3);
		world.setBlock(x + 2, y + 4, z + 5, Blocks.glass, 0, 3);
		world.setBlock(x + 3, y + 4, z + 5, Blocks.glass, 0, 3);
		world.setBlock(x + 4, y + 4, z + 5, Blocks.glass, 0, 3);
		world.setBlock(x + 5, y + 4, z + 5, Blocks.glass, 0, 3);
		world.setBlock(x + 6, y + 4, z + 5, Blocks.glass, 0, 3);
		world.setBlock(x + 7, y + 4, z + 5, Blocks.glass, 0, 3);
		world.setBlock(x + 1, y + 4, z + 6, Blocks.glass, 0, 3);
		world.setBlock(x + 2, y + 4, z + 6, Blocks.glass, 0, 3);
		world.setBlock(x + 3, y + 4, z + 6, Blocks.glass, 0, 3);
		world.setBlock(x + 4, y + 4, z + 6, Blocks.glass, 0, 3);
		world.setBlock(x + 5, y + 4, z + 6, Blocks.glass, 0, 3);
		world.setBlock(x + 6, y + 4, z + 6, Blocks.glass, 0, 3);
		world.setBlock(x + 7, y + 4, z + 6, Blocks.glass, 0, 3);
		world.setBlock(x + 1, y + 4, z + 7, Blocks.glass, 0, 3);
		world.setBlock(x + 2, y + 4, z + 7, Blocks.glass, 0, 3);
		world.setBlock(x + 3, y + 4, z + 7, Blocks.glass, 0, 3);
		world.setBlock(x + 4, y + 4, z + 7, Blocks.glass, 0, 3);
		world.setBlock(x + 5, y + 4, z + 7, Blocks.glass, 0, 3);
		world.setBlock(x + 6, y + 4, z + 7, Blocks.glass, 0, 3);
		world.setBlock(x + 7, y + 4, z + 7, Blocks.glass, 0, 3);
		world.setBlock(x + 1, y + 4, z + 8, Blocks.glass, 0, 3);
		world.setBlock(x + 2, y + 4, z + 8, Blocks.glass, 0, 3);
		world.setBlock(x + 3, y + 4, z + 8, Blocks.glass, 0, 3);
		world.setBlock(x + 4, y + 4, z + 8, Blocks.glass, 0, 3);
		world.setBlock(x + 5, y + 4, z + 8, Blocks.glass, 0, 3);
		world.setBlock(x + 6, y + 4, z + 8, Blocks.glass, 0, 3);
		world.setBlock(x + 7, y + 4, z + 8, Blocks.glass, 0, 3);
		world.setBlock(x + 2, y + 4, z + 9, Blocks.glass, 0, 3);
		world.setBlock(x + 3, y + 4, z + 9, Blocks.glass, 0, 3);
		world.setBlock(x + 4, y + 4, z + 9, Blocks.glass, 0, 3);
		world.setBlock(x + 5, y + 4, z + 9, Blocks.glass, 0, 3);
		world.setBlock(x + 6, y + 4, z + 9, Blocks.glass, 0, 3);
		world.setBlock(x + 7, y + 4, z + 9, Blocks.glass, 0, 3);
		world.setBlock(x + 3, y + 4, z + 10, Blocks.glass, 0, 3);
		world.setBlock(x + 4, y + 4, z + 10, Blocks.glass, 0, 3);
		world.setBlock(x + 5, y + 4, z + 10, Blocks.glass, 0, 3);
		world.setBlock(x + 6, y + 4, z + 10, Blocks.glass, 0, 3);
		world.setBlock(x + 4, y + 4, z + 11, Blocks.glass, 0, 3);
		world.setBlock(x + 5, y + 4, z + 11, Blocks.glass, 0, 3);
		return true;
	}
}


